<?xml version="1.0" ?>
<robot name="InMoov_to_URDF">

<material name="silver">
  <color rgba="0.700 0.700 0.700 1.000"/>
</material>

<link name="base_link">
  <inertial>
    <origin xyz="-0.07916174673309954 0.05728371380043015 -0.03479724209721192" rpy="0 0 0"/>
    <mass value="0.6648547297102684"/>
    <inertia ixx="0.0009133777749627914" iyy="0.0005144006849392303" izz="0.0013764815731680717" ixy="-5.385079326415557e-05" iyz="-2.8993185183278378e-05" ixz="3.092343352191799e-05"/>
  </inertial>
  <visual>
    <origin xyz="0 0 0" rpy="0 0 0"/>
    <geometry>
      <mesh filename="meshes/base_link.stl" scale="0.001 0.001 0.001"/>
    </geometry>
    <material name="silver"/>
    <material/>
  </visual>
  <collision>
    <origin xyz="0 0 0" rpy="0 0 0"/>
    <geometry>
      <mesh filename="meshes/base_link.stl" scale="0.001 0.001 0.001"/>
    </geometry>
  </collision>
</link>

<link name="i2_Finger_M11">
  <inertial>
    <origin xyz="0.08769264188814799 -0.020629596863948746 -0.0539947503166449" rpy="0 0 0"/>
    <mass value="0.06162016776927652"/>
    <inertia ixx="4.045856811327799e-06" iyy="9.086672329493539e-06" izz="9.350790613681521e-06" ixy="-1.8662942047371838e-06" iyz="-3.822930579258784e-07" ixz="-1.4362416850001222e-06"/>
  </inertial>
  <visual>
    <origin xyz="0.105741 -0.053152 -0.018959" rpy="0 0 0"/>
    <geometry>
      <mesh filename="meshes/i2_Finger_M11.stl" scale="0.001 0.001 0.001"/>
    </geometry>
    <material name="silver"/>
    <material/>
  </visual>
  <collision>
    <origin xyz="0.105741 -0.053152 -0.018959" rpy="0 0 0"/>
    <geometry>
      <mesh filename="meshes/i2_Finger_M11.stl" scale="0.001 0.001 0.001"/>
    </geometry>
  </collision>
</link>

<link name="i2_Finger_Tip_M11">
  <inertial>
    <origin xyz="0.07220964183720088 0.0007821096079932421 -0.038336792697067336" rpy="0 0 0"/>
    <mass value="0.07639377520772606"/>
    <inertia ixx="8.401134424772884e-06" iyy="1.2616393011331523e-05" izz="1.3239560749322992e-05" ixy="-4.545578519495328e-06" iyz="-2.438133803656407e-06" ixz="-4.0483650753957996e-06"/>
  </inertial>
  <visual>
    <origin xyz="0.056848 -0.047168 -0.016522" rpy="0 0 0"/>
    <geometry>
      <mesh filename="meshes/i2_Finger_Tip_M11.stl" scale="0.001 0.001 0.001"/>
    </geometry>
    <material name="silver"/>
    <material/>
  </visual>
  <collision>
    <origin xyz="0.056848 -0.047168 -0.016522" rpy="0 0 0"/>
    <geometry>
      <mesh filename="meshes/i2_Finger_Tip_M11.stl" scale="0.001 0.001 0.001"/>
    </geometry>
  </collision>
</link>

<link name="i2_Finger_Tip_M41">
  <inertial>
    <origin xyz="0.08306721511967549 0.23281099575459646 -0.030694956122969637" rpy="0 0 0"/>
    <mass value="0.03805905894003434"/>
    <inertia ixx="4.31971285747468e-06" iyy="1.0595502069663367e-06" izz="4.377770388480293e-06" ixy="-5.6434586121660926e-08" iyz="-2.688308039280863e-07" ixz="3.120277607243627e-09"/>
  </inertial>
  <visual>
    <origin xyz="0.19823 0.061219 -0.006313" rpy="0 0 0"/>
    <geometry>
      <mesh filename="meshes/i2_Finger_Tip_M41.stl" scale="0.001 0.001 0.001"/>
    </geometry>
    <material name="silver"/>
    <material/>
  </visual>
  <collision>
    <origin xyz="0.19823 0.061219 -0.006313" rpy="0 0 0"/>
    <geometry>
      <mesh filename="meshes/i2_Finger_Tip_M41.stl" scale="0.001 0.001 0.001"/>
    </geometry>
  </collision>
</link>

<link name="i2_Finger_Top_M41">
  <inertial>
    <origin xyz="0.08094381585535212 0.1801255788378644 -0.028948769946589945" rpy="0 0 0"/>
    <mass value="0.029364177338737477"/>
    <inertia ixx="2.8663632393843407e-06" iyy="1.0274108756399506e-06" izz="2.93251758481548e-06" ixy="-2.172193187566793e-08" iyz="-2.6611654171013427e-08" ixz="3.6121618386691532e-09"/>
  </inertial>
  <visual>
    <origin xyz="0.196638 0.037468 -0.003129" rpy="0 0 0"/>
    <geometry>
      <mesh filename="meshes/i2_Finger_Top_M41.stl" scale="0.001 0.001 0.001"/>
    </geometry>
    <material name="silver"/>
    <material/>
  </visual>
  <collision>
    <origin xyz="0.196638 0.037468 -0.003129" rpy="0 0 0"/>
    <geometry>
      <mesh filename="meshes/i2_Finger_Top_M41.stl" scale="0.001 0.001 0.001"/>
    </geometry>
  </collision>
</link>

<link name="i2_Finger_Bot_M41">
  <inertial>
    <origin xyz="0.08486657469687223 0.10931022461019858 -0.039317592539338454" rpy="0 0 0"/>
    <mass value="0.05749950266073279"/>
    <inertia ixx="8.305285855579776e-06" iyy="2.7232951231851614e-06" izz="8.359973921207454e-06" ixy="-8.647886310655592e-08" iyz="-2.13852789905227e-07" ixz="1.711341259132658e-10"/>
  </inertial>
  <visual>
    <origin xyz="0.201035 -0.003804 -0.010984" rpy="0 0 0"/>
    <geometry>
      <mesh filename="meshes/i2_Finger_Bot_M41.stl" scale="0.001 0.001 0.001"/>
    </geometry>
    <material name="silver"/>
    <material/>
  </visual>
  <collision>
    <origin xyz="0.201035 -0.003804 -0.010984" rpy="0 0 0"/>
    <geometry>
      <mesh filename="meshes/i2_Finger_Bot_M41.stl" scale="0.001 0.001 0.001"/>
    </geometry>
  </collision>
</link>

<link name="i2_Finger_Tip_M43">
  <inertial>
    <origin xyz="0.10116328612448716 0.22566549680563314 -0.029737285690797366" rpy="0 0 0"/>
    <mass value="0.03805905894003434"/>
    <inertia ixx="4.290318737172182e-06" iyy="1.0917383963886772e-06" izz="4.374976319359257e-06" ixy="-3.13369401093856e-07" iyz="-2.846521703510341e-07" ixz="-1.9605089084538045e-08"/>
  </inertial>
  <visual>
    <origin xyz="0.183777 0.042699 -0.003997" rpy="0 0 0"/>
    <geometry>
      <mesh filename="meshes/i2_Finger_Tip_M43.stl" scale="0.001 0.001 0.001"/>
    </geometry>
    <material name="silver"/>
    <material/>
  </visual>
  <collision>
    <origin xyz="0.183777 0.042699 -0.003997" rpy="0 0 0"/>
    <geometry>
      <mesh filename="meshes/i2_Finger_Tip_M43.stl" scale="0.001 0.001 0.001"/>
    </geometry>
  </collision>
</link>

<link name="i2_Finger_Top_M43">
  <inertial>
    <origin xyz="0.09488191175458985 0.17330469258262593 -0.028250809438347832" rpy="0 0 0"/>
    <mass value="0.029364177338737477"/>
    <inertia ixx="2.8514283449851364e-06" iyy="1.042678739799751e-06" izz="2.9321846150547753e-06" ixy="-1.6657317245037748e-07" iyz="-3.6284606699668945e-08" ixz="8.019891930324255e-10"/>
  </inertial>
  <visual>
    <origin xyz="0.180318 0.019132 -0.000929" rpy="0 0 0"/>
    <geometry>
      <mesh filename="meshes/i2_Finger_Top_M43.stl" scale="0.001 0.001 0.001"/>
    </geometry>
    <material name="silver"/>
    <material/>
  </visual>
  <collision>
    <origin xyz="0.180318 0.019132 -0.000929" rpy="0 0 0"/>
    <geometry>
      <mesh filename="meshes/i2_Finger_Top_M43.stl" scale="0.001 0.001 0.001"/>
    </geometry>
  </collision>
</link>

<link name="i2_Finger_Bot_M43">
  <inertial>
    <origin xyz="0.08880903571463318 0.13799294034746262 -0.040397523320779075" rpy="0 0 0"/>
    <mass value="0.05749950266073279"/>
    <inertia ixx="8.256619664448006e-06" iyy="2.7742465917053724e-06" izz="8.357688643819989e-06" ixy="-5.26074345143907e-07" iyz="-2.4111613031280415e-07" ixz="-1.9266550510017985e-08"/>
  </inertial>
  <visual>
    <origin xyz="0.177061 0.01322 -0.010415" rpy="0 0 0"/>
    <geometry>
      <mesh filename="meshes/i2_Finger_Bot_M43.stl" scale="0.001 0.001 0.001"/>
    </geometry>
    <material name="silver"/>
    <material/>
  </visual>
  <collision>
    <origin xyz="0.177061 0.01322 -0.010415" rpy="0 0 0"/>
    <geometry>
      <mesh filename="meshes/i2_Finger_Bot_M43.stl" scale="0.001 0.001 0.001"/>
    </geometry>
  </collision>
</link>

<link name="i2_Finger_Tip_M44">
  <inertial>
    <origin xyz="0.11887082939001259 0.21492792471645125 -0.04146782530520329" rpy="0 0 0"/>
    <mass value="0.03805905894003434"/>
    <inertia ixx="4.217363883686357e-06" iyy="1.1446410744221321e-06" izz="4.3950284948118985e-06" ixy="-5.730714672031638e-07" iyz="-1.1949001027920943e-07" ixz="-1.3309036120534167e-08"/>
  </inertial>
  <visual>
    <origin xyz="0.167497 0.024786 -0.010487" rpy="0 0 0"/>
    <geometry>
      <mesh filename="meshes/i2_Finger_Tip_M44.stl" scale="0.001 0.001 0.001"/>
    </geometry>
    <material name="silver"/>
    <material/>
  </visual>
  <collision>
    <origin xyz="0.167497 0.024786 -0.010487" rpy="0 0 0"/>
    <geometry>
      <mesh filename="meshes/i2_Finger_Tip_M44.stl" scale="0.001 0.001 0.001"/>
    </geometry>
  </collision>
</link>

<link name="i2_Finger_Top_M44">
  <inertial>
    <origin xyz="0.10836298792456506 0.1633899802981582 -0.03736989238472856" rpy="0 0 0"/>
    <mass value="0.029364177338737477"/>
    <inertia ixx="2.8123780308788844e-06" iyy="1.0828497400093144e-06" izz="2.931063928950854e-06" ixy="-3.111735161584364e-07" iyz="5.668236293442726e-08" ixz="1.4206593845157082e-08"/>
  </inertial>
  <visual>
    <origin xyz="0.162163 0.001757 -0.006242" rpy="0 0 0"/>
    <geometry>
      <mesh filename="meshes/i2_Finger_Top_M44.stl" scale="0.001 0.001 0.001"/>
    </geometry>
    <material name="silver"/>
    <material/>
  </visual>
  <collision>
    <origin xyz="0.162163 0.001757 -0.006242" rpy="0 0 0"/>
    <geometry>
      <mesh filename="meshes/i2_Finger_Top_M44.stl" scale="0.001 0.001 0.001"/>
    </geometry>
  </collision>
</link>

<link name="i2_Finger_Bot_M44">
  <inertial>
    <origin xyz="0.09183763229013153 0.15761210931654485 -0.041967126968931505" rpy="0 0 0"/>
    <mass value="0.05749950266073279"/>
    <inertia ixx="8.134104424619044e-06" iyy="2.88666720084992e-06" izz="8.367783274503644e-06" ixy="-9.670828447250505e-07" iyz="3.663308901342109e-08" ixz="1.0369186387036212e-08"/>
  </inertial>
  <visual>
    <origin xyz="0.150866 0.025144 -0.009644" rpy="0 0 0"/>
    <geometry>
      <mesh filename="meshes/i2_Finger_Bot_M44.stl" scale="0.001 0.001 0.001"/>
    </geometry>
    <material name="silver"/>
    <material/>
  </visual>
  <collision>
    <origin xyz="0.150866 0.025144 -0.009644" rpy="0 0 0"/>
    <geometry>
      <mesh filename="meshes/i2_Finger_Bot_M44.stl" scale="0.001 0.001 0.001"/>
    </geometry>
  </collision>
</link>

<link name="i2_Finger_Tip_M45">
  <inertial>
    <origin xyz="0.13456825708135473 0.20557527055443112 -0.04091164392444335" rpy="0 0 0"/>
    <mass value="0.03805905894003434"/>
    <inertia ixx="4.114739861161643e-06" iyy="1.248022416511578e-06" izz="4.394271175243731e-06" ixy="-7.957034862530782e-07" iyz="-1.2769488042096576e-07" ixz="-2.4548993139792297e-08"/>
  </inertial>
  <visual>
    <origin xyz="0.154411 0.03037 -0.008036" rpy="0 0 0"/>
    <geometry>
      <mesh filename="meshes/i2_Finger_Tip_M45.stl" scale="0.001 0.001 0.001"/>
    </geometry>
    <material name="silver"/>
    <material/>
  </visual>
  <collision>
    <origin xyz="0.154411 0.03037 -0.008036" rpy="0 0 0"/>
    <geometry>
      <mesh filename="meshes/i2_Finger_Tip_M45.stl" scale="0.001 0.001 0.001"/>
    </geometry>
  </collision>
</link>

<link name="i2_Finger_Top_M45">
  <inertial>
    <origin xyz="0.12024200058589363 0.15495436301295573 -0.03696650109283456" rpy="0 0 0"/>
    <mass value="0.029364177338737477"/>
    <inertia ixx="2.7563623149383853e-06" iyy="1.1385531052551e-06" izz="2.9313762796457504e-06" ixy="-4.3661358590274296e-07" iyz="5.001827234807268e-08" ixz="1.7132915405793455e-08"/>
  </inertial>
  <visual>
    <origin xyz="0.147375 0.007791 -0.003859" rpy="0 0 0"/>
    <geometry>
      <mesh filename="meshes/i2_Finger_Top_M45.stl" scale="0.001 0.001 0.001"/>
    </geometry>
    <material name="silver"/>
    <material/>
  </visual>
  <collision>
    <origin xyz="0.147375 0.007791 -0.003859" rpy="0 0 0"/>
    <geometry>
      <mesh filename="meshes/i2_Finger_Top_M45.stl" scale="0.001 0.001 0.001"/>
    </geometry>
  </collision>
</link>

<link name="i2_Finger_Bot_M45">
  <inertial>
    <origin xyz="0.09105750739946888 0.13451383154067875 -0.044760538613985656" rpy="0 0 0"/>
    <mass value="0.05749950266073279"/>
    <inertia ixx="7.960657158541233e-06" iyy="3.0599531113719976e-06" izz="8.367944630058863e-06" ixy="-1.3473836692764292e-06" iyz="1.9680181388264653e-08" ixz="9.050326343928473e-09"/>
  </inertial>
  <visual>
    <origin xyz="0.125585 0.016039 -0.010371" rpy="0 0 0"/>
    <geometry>
      <mesh filename="meshes/i2_Finger_Bot_M45.stl" scale="0.001 0.001 0.001"/>
    </geometry>
    <material name="silver"/>
    <material/>
  </visual>
  <collision>
    <origin xyz="0.125585 0.016039 -0.010371" rpy="0 0 0"/>
    <geometry>
      <mesh filename="meshes/i2_Finger_Bot_M45.stl" scale="0.001 0.001 0.001"/>
    </geometry>
  </collision>
</link>

<joint name="Revolute_2" type="revolute">
  <origin xyz="-0.105741 0.053152 0.018959" rpy="0 0 0"/>
  <parent link="base_link"/>
  <child link="i2_Finger_M11"/>
  <axis xyz="0.063711 -0.724004 0.686847"/>
  <limit upper="0.872665" lower="0.0" effort="100" velocity="100"/>
</joint>
<transmission name="Revolute_2_tran">
  <type>transmission_interface/SimpleTransmission</type>
  <joint name="Revolute_2">
    <hardwareInterface>PositionJointInterface</hardwareInterface>
  </joint>
  <actuator name="Revolute_2_actr">
    <hardwareInterface>PositionJointInterface</hardwareInterface>
    <mechanicalReduction>1</mechanicalReduction>
  </actuator>
</transmission>

<joint name="Revolute_3" type="revolute">
  <origin xyz="0.048893 -0.005984 -0.002437" rpy="0 0 0"/>
  <parent link="i2_Finger_M11"/>
  <child link="i2_Finger_Tip_M11"/>
  <axis xyz="0.063713 -0.724005 0.686846"/>
  <limit upper="0.523599" lower="0.0" effort="100" velocity="100"/>
</joint>
<transmission name="Revolute_3_tran">
  <type>transmission_interface/SimpleTransmission</type>
  <joint name="Revolute_3">
    <hardwareInterface>PositionJointInterface</hardwareInterface>
  </joint>
  <actuator name="Revolute_3_actr">
    <hardwareInterface>PositionJointInterface</hardwareInterface>
    <mechanicalReduction>1</mechanicalReduction>
  </actuator>
</transmission>

<joint name="Revolute_5" type="revolute">
  <origin xyz="-0.001592 -0.023751 0.003184" rpy="0 0 0"/>
  <parent link="i2_Finger_Top_M41"/>
  <child link="i2_Finger_Tip_M41"/>
  <axis xyz="0.997587 -0.010774 -0.068593"/>
  <limit upper="1.396263" lower="0.0" effort="100" velocity="100"/>
</joint>
<transmission name="Revolute_5_tran">
  <type>transmission_interface/SimpleTransmission</type>
  <joint name="Revolute_5">
    <hardwareInterface>PositionJointInterface</hardwareInterface>
  </joint>
  <actuator name="Revolute_5_actr">
    <hardwareInterface>PositionJointInterface</hardwareInterface>
    <mechanicalReduction>1</mechanicalReduction>
  </actuator>
</transmission>

<joint name="Revolute_6" type="revolute">
  <origin xyz="0.004397 -0.041272 -0.007855" rpy="0 0 0"/>
  <parent link="i2_Finger_Bot_M41"/>
  <child link="i2_Finger_Top_M41"/>
  <axis xyz="0.997587 -0.01078 -0.068591"/>
  <limit upper="1.658063" lower="0.0" effort="100" velocity="100"/>
</joint>
<transmission name="Revolute_6_tran">
  <type>transmission_interface/SimpleTransmission</type>
  <joint name="Revolute_6">
    <hardwareInterface>PositionJointInterface</hardwareInterface>
  </joint>
  <actuator name="Revolute_6_actr">
    <hardwareInterface>PositionJointInterface</hardwareInterface>
    <mechanicalReduction>1</mechanicalReduction>
  </actuator>
</transmission>

<joint name="Revolute_7" type="revolute">
  <origin xyz="-0.201035 0.003804 0.010984" rpy="0 0 0"/>
  <parent link="base_link"/>
  <child link="i2_Finger_Bot_M41"/>
  <axis xyz="0.997587 -0.010781 -0.068593"/>
  <limit upper="1.570796" lower="0.0" effort="100" velocity="100"/>
</joint>
<transmission name="Revolute_7_tran">
  <type>transmission_interface/SimpleTransmission</type>
  <joint name="Revolute_7">
    <hardwareInterface>PositionJointInterface</hardwareInterface>
  </joint>
  <actuator name="Revolute_7_actr">
    <hardwareInterface>PositionJointInterface</hardwareInterface>
    <mechanicalReduction>1</mechanicalReduction>
  </actuator>
</transmission>

<joint name="Revolute_8" type="revolute">
  <origin xyz="-0.003459 -0.023567 0.003068" rpy="0 0 0"/>
  <parent link="i2_Finger_Top_M43"/>
  <child link="i2_Finger_Tip_M43"/>
  <axis xyz="0.993457 -0.089311 -0.071177"/>
  <limit upper="1.396263" lower="0.0" effort="100" velocity="100"/>
</joint>
<transmission name="Revolute_8_tran">
  <type>transmission_interface/SimpleTransmission</type>
  <joint name="Revolute_8">
    <hardwareInterface>PositionJointInterface</hardwareInterface>
  </joint>
  <actuator name="Revolute_8_actr">
    <hardwareInterface>PositionJointInterface</hardwareInterface>
    <mechanicalReduction>1</mechanicalReduction>
  </actuator>
</transmission>

<joint name="Revolute_9" type="revolute">
  <origin xyz="-0.003257 -0.005912 -0.009486" rpy="0 0 0"/>
  <parent link="i2_Finger_Bot_M43"/>
  <child link="i2_Finger_Top_M43"/>
  <axis xyz="0.993457 -0.089316 -0.071176"/>
  <limit upper="1.658063" lower="0.0" effort="100" velocity="100"/>
</joint>
<transmission name="Revolute_9_tran">
  <type>transmission_interface/SimpleTransmission</type>
  <joint name="Revolute_9">
    <hardwareInterface>PositionJointInterface</hardwareInterface>
  </joint>
  <actuator name="Revolute_9_actr">
    <hardwareInterface>PositionJointInterface</hardwareInterface>
    <mechanicalReduction>1</mechanicalReduction>
  </actuator>
</transmission>

<joint name="Revolute_10" type="revolute">
  <origin xyz="-0.177061 -0.01322 0.010415" rpy="0 0 0"/>
  <parent link="base_link"/>
  <child link="i2_Finger_Bot_M43"/>
  <axis xyz="0.993457 -0.089317 -0.071177"/>
  <limit upper="1.570796" lower="0.0" effort="100" velocity="100"/>
</joint>
<transmission name="Revolute_10_tran">
  <type>transmission_interface/SimpleTransmission</type>
  <joint name="Revolute_10">
    <hardwareInterface>PositionJointInterface</hardwareInterface>
  </joint>
  <actuator name="Revolute_10_actr">
    <hardwareInterface>PositionJointInterface</hardwareInterface>
    <mechanicalReduction>1</mechanicalReduction>
  </actuator>
</transmission>

<joint name="Revolute_11" type="revolute">
  <origin xyz="-0.005334 -0.023029 0.004245" rpy="0 0 0"/>
  <parent link="i2_Finger_Top_M44"/>
  <child link="i2_Finger_Tip_M44"/>
  <axis xyz="0.982063 -0.173647 -0.073485"/>
  <limit upper="1.396263" lower="0.0" effort="100" velocity="100"/>
</joint>
<transmission name="Revolute_11_tran">
  <type>transmission_interface/SimpleTransmission</type>
  <joint name="Revolute_11">
    <hardwareInterface>PositionJointInterface</hardwareInterface>
  </joint>
  <actuator name="Revolute_11_actr">
    <hardwareInterface>PositionJointInterface</hardwareInterface>
    <mechanicalReduction>1</mechanicalReduction>
  </actuator>
</transmission>

<joint name="Revolute_12" type="revolute">
  <origin xyz="-0.011297 0.023387 -0.003402" rpy="0 0 0"/>
  <parent link="i2_Finger_Bot_M44"/>
  <child link="i2_Finger_Top_M44"/>
  <axis xyz="0.982062 -0.173652 -0.073483"/>
  <limit upper="1.658063" lower="0.0" effort="100" velocity="100"/>
</joint>
<transmission name="Revolute_12_tran">
  <type>transmission_interface/SimpleTransmission</type>
  <joint name="Revolute_12">
    <hardwareInterface>PositionJointInterface</hardwareInterface>
  </joint>
  <actuator name="Revolute_12_actr">
    <hardwareInterface>PositionJointInterface</hardwareInterface>
    <mechanicalReduction>1</mechanicalReduction>
  </actuator>
</transmission>

<joint name="Revolute_13" type="revolute">
  <origin xyz="-0.150866 -0.025144 0.009644" rpy="0 0 0"/>
  <parent link="base_link"/>
  <child link="i2_Finger_Bot_M44"/>
  <axis xyz="0.982061 -0.173653 -0.073484"/>
  <limit upper="1.570796" lower="0.0" effort="100" velocity="100"/>
</joint>
<transmission name="Revolute_13_tran">
  <type>transmission_interface/SimpleTransmission</type>
  <joint name="Revolute_13">
    <hardwareInterface>PositionJointInterface</hardwareInterface>
  </joint>
  <actuator name="Revolute_13_actr">
    <hardwareInterface>PositionJointInterface</hardwareInterface>
    <mechanicalReduction>1</mechanicalReduction>
  </actuator>
</transmission>

<joint name="Revolute_14" type="revolute">
  <origin xyz="-0.007036 -0.022579 0.004177" rpy="0 0 0"/>
  <parent link="i2_Finger_Top_M45"/>
  <child link="i2_Finger_Tip_M45"/>
  <axis xyz="0.966277 -0.246319 -0.075066"/>
  <limit upper="1.396263" lower="0.0" effort="100" velocity="100"/>
</joint>
<transmission name="Revolute_14_tran">
  <type>transmission_interface/SimpleTransmission</type>
  <joint name="Revolute_14">
    <hardwareInterface>PositionJointInterface</hardwareInterface>
  </joint>
  <actuator name="Revolute_14_actr">
    <hardwareInterface>PositionJointInterface</hardwareInterface>
    <mechanicalReduction>1</mechanicalReduction>
  </actuator>
</transmission>

<joint name="Revolute_15" type="revolute">
  <origin xyz="-0.02179 0.008248 -0.006512" rpy="0 0 0"/>
  <parent link="i2_Finger_Bot_M45"/>
  <child link="i2_Finger_Top_M45"/>
  <axis xyz="0.966276 -0.246325 -0.075065"/>
  <limit upper="1.658063" lower="0.0" effort="100" velocity="100"/>
</joint>
<transmission name="Revolute_15_tran">
  <type>transmission_interface/SimpleTransmission</type>
  <joint name="Revolute_15">
    <hardwareInterface>PositionJointInterface</hardwareInterface>
  </joint>
  <actuator name="Revolute_15_actr">
    <hardwareInterface>PositionJointInterface</hardwareInterface>
    <mechanicalReduction>1</mechanicalReduction>
  </actuator>
</transmission>

<joint name="Revolute_16" type="revolute">
  <origin xyz="-0.125585 -0.016039 0.010371" rpy="0 0 0"/>
  <parent link="base_link"/>
  <child link="i2_Finger_Bot_M45"/>
  <axis xyz="0.966276 -0.246326 -0.075066"/>
  <limit upper="1.570796" lower="0.0" effort="100" velocity="100"/>
</joint>
<transmission name="Revolute_16_tran">
  <type>transmission_interface/SimpleTransmission</type>
  <joint name="Revolute_16">
    <hardwareInterface>PositionJointInterface</hardwareInterface>
  </joint>
  <actuator name="Revolute_16_actr">
    <hardwareInterface>PositionJointInterface</hardwareInterface>
    <mechanicalReduction>1</mechanicalReduction>
  </actuator>
</transmission>

</robot>
